<sdf version='1.7'>
  <world name='default'>
    <light name='sun' type='directional'>
      <cast_shadows>1</cast_shadows>
      <pose>0 0 10 0 -0 0</pose>
      <diffuse>0.8 0.8 0.8 1</diffuse>
      <specular>0.2 0.2 0.2 1</specular>
      <attenuation>
        <range>1000</range>
        <constant>0.9</constant>
        <linear>0.01</linear>
        <quadratic>0.001</quadratic>
      </attenuation>
      <direction>-0.5 0.1 -0.9</direction>
      <spot>
        <inner_angle>0</inner_angle>
        <outer_angle>0</outer_angle>
        <falloff>0</falloff>
      </spot>
    </light>
    <gravity>0 0 -9.8</gravity>
    <magnetic_field>6e-06 2.3e-05 -4.2e-05</magnetic_field>
    <atmosphere type='adiabatic'/>
    <physics type='ode'>
      <max_step_size>0.001</max_step_size>
      <real_time_factor>1</real_time_factor>
      <real_time_update_rate>1000</real_time_update_rate>
    </physics>
    <scene>
      <ambient>0.4 0.4 0.4 1</ambient>
      <background>0.7 0.7 0.7 1</background>
      <shadows>1</shadows>
    </scene>
    <wind/>
    <spherical_coordinates>
      <surface_model>EARTH_WGS84</surface_model>
      <latitude_deg>0</latitude_deg>
      <longitude_deg>0</longitude_deg>
      <elevation>0</elevation>
      <heading_deg>0</heading_deg>
    </spherical_coordinates>
    <model name='my_ground_plane'>
      <static>1</static>
      <link name='link'>
        <collision name='collision'>
          <geometry>
            <plane>
              <normal>0 0 1</normal>
              <size>10000 10000</size>
            </plane>
          </geometry>
          <surface>
            <friction>
              <ode>
                <mu>100</mu>
                <mu2>50</mu2>
              </ode>
              <torsional>
                <ode/>
              </torsional>
            </friction>
            <contact>
              <ode/>
            </contact>
            <bounce/>
          </surface>
          <max_contacts>10</max_contacts>
        </collision>
        <visual name='visual'>
          <cast_shadows>0</cast_shadows>
          <geometry>
            <plane>
              <normal>0 0 1</normal>
              <size>30 30</size>
            </plane>
          </geometry>
          <material>
            <script>
              <uri>model://my_ground_plane/materials/scripts</uri>
              <uri>model://my_ground_plane/materials/textures/</uri>
              <name>MyGroundPlane/Image</name>
            </script>
          </material>
        </visual>
        <self_collide>0</self_collide>
        <enable_wind>0</enable_wind>
        <kinematic>0</kinematic>
      </link>
      <pose>5.49276 7.39463 0 0 -0 0</pose>
    </model>
    <model name='law_office'>
      <static>1</static>
      <link name='link'>
        <collision name='collision'>
          <pose>0 0 6.96244 0 -0 0</pose>
          <geometry>
            <box>
              <size>6.84401 5.43165 13.9249</size>
            </box>
          </geometry>
          <max_contacts>10</max_contacts>
          <surface>
            <contact>
              <ode/>
            </contact>
            <bounce/>
            <friction>
              <torsional>
                <ode/>
              </torsional>
              <ode/>
            </friction>
          </surface>
        </collision>
        <visual name='visual'>
          <geometry>
            <mesh>
              <uri>model://law_office/meshes/law_office.dae</uri>
            </mesh>
          </geometry>
        </visual>
        <self_collide>0</self_collide>
        <enable_wind>0</enable_wind>
        <kinematic>0</kinematic>
      </link>
      <pose>-4.97303 19.8734 0 0 -0 0</pose>
    </model>
    <model name='House 1'>
      <static>1</static>
      <link name='link'>
        <collision name='collision'>
          <geometry>
            <mesh>
              <uri>model://house_1/meshes/house_1.dae</uri>
              <scale>1.5 1.5 1.5</scale>
            </mesh>
          </geometry>
          <max_contacts>10</max_contacts>
          <surface>
            <contact>
              <ode/>
            </contact>
            <bounce/>
            <friction>
              <torsional>
                <ode/>
              </torsional>
              <ode/>
            </friction>
          </surface>
        </collision>
        <visual name='visual'>
          <geometry>
            <mesh>
              <uri>model://house_1/meshes/house_1.dae</uri>
              <scale>1.5 1.5 1.5</scale>
            </mesh>
          </geometry>
          <material>
            <script>
              <uri>model://house_1/materials/scripts</uri>
              <uri>model://house_1/materials/textures</uri>
              <name>House_1/Diffuse</name>
            </script>
            <shader type='normal_map_tangent_space'>
              <normal_map>House_1_Normal.png</normal_map>
            </shader>
          </material>
        </visual>
        <self_collide>0</self_collide>
        <enable_wind>0</enable_wind>
        <kinematic>0</kinematic>
      </link>
      <pose>9.98872 24.7095 0 0 -0 0</pose>
    </model>
    <model name='House 2'>
      <static>1</static>
      <link name='link'>
        <collision name='collision'>
          <geometry>
            <mesh>
              <uri>model://house_2/meshes/house_2.dae</uri>
              <scale>1.5 1.5 1.5</scale>
            </mesh>
          </geometry>
          <max_contacts>10</max_contacts>
          <surface>
            <contact>
              <ode/>
            </contact>
            <bounce/>
            <friction>
              <torsional>
                <ode/>
              </torsional>
              <ode/>
            </friction>
          </surface>
        </collision>
        <visual name='visual'>
          <geometry>
            <mesh>
              <uri>model://house_2/meshes/house_2.dae</uri>
              <scale>1.5 1.5 1.5</scale>
            </mesh>
          </geometry>
          <material>
            <script>
              <uri>model://house_2/materials/scripts</uri>
              <uri>model://house_2/materials/textures</uri>
              <uri>model://house_1/materials/textures</uri>
              <name>House_2/Diffuse</name>
            </script>
            <shader type='normal_map_tangent_space'>
              <normal_map>model://house_1/materials/textures/House_1_Normal.png</normal_map>
            </shader>
          </material>
        </visual>
        <self_collide>0</self_collide>
        <enable_wind>0</enable_wind>
        <kinematic>0</kinematic>
      </link>
      <pose>26.0838 19.832 0 0 -0 0</pose>
    </model>
    <model name='thrift_shop'>
      <static>1</static>
      <link name='link'>
        <collision name='collision'>
          <pose>0 0 5.69469 0 -0 0</pose>
          <geometry>
            <box>
              <size>7.21297 5.43165 11.3894</size>
            </box>
          </geometry>
          <max_contacts>10</max_contacts>
          <surface>
            <contact>
              <ode/>
            </contact>
            <bounce/>
            <friction>
              <torsional>
                <ode/>
              </torsional>
              <ode/>
            </friction>
          </surface>
        </collision>
        <visual name='visual'>
          <pose>0 -0.912491 0 0 -0 0</pose>
          <geometry>
            <mesh>
              <uri>model://thrift_shop/meshes/thrift_shop.dae</uri>
            </mesh>
          </geometry>
        </visual>
        <self_collide>0</self_collide>
        <enable_wind>0</enable_wind>
        <kinematic>0</kinematic>
      </link>
      <pose>26.2701 6.54385 0 0 -0 0</pose>
    </model>
    <state world_name='default'>
      <sim_time>231 846000000</sim_time>
      <real_time>233 506228349</real_time>
      <wall_time>1714976099 635003708</wall_time>
      <iterations>231846</iterations>
      <model name='House 1'>
        <pose>10.2125 21.1847 0 0 -0 0</pose>
        <scale>1 1 1</scale>
        <link name='link'>
          <pose>10.2125 21.1847 0 0 -0 0</pose>
          <velocity>0 0 0 0 -0 0</velocity>
          <acceleration>0 0 0 0 -0 0</acceleration>
          <wrench>0 0 0 0 -0 0</wrench>
        </link>
      </model>
      <model name='House 2'>
        <pose>13.8461 -5.31219 0 0 -0 0</pose>
        <scale>1 1 1</scale>
        <link name='link'>
          <pose>13.8461 -5.31219 0 0 -0 0</pose>
          <velocity>0 0 0 0 -0 0</velocity>
          <acceleration>0 0 0 0 -0 0</acceleration>
          <wrench>0 0 0 0 -0 0</wrench>
        </link>
      </model>
      <model name='law_office'>
        <pose>-4.97303 -6.37371 0 0 -0 0</pose>
        <scale>1 1 1</scale>
        <link name='link'>
          <pose>-4.97303 -6.37371 0 0 -0 0</pose>
          <velocity>0 0 0 0 -0 0</velocity>
          <acceleration>0 0 0 0 -0 0</acceleration>
          <wrench>0 0 0 0 -0 0</wrench>
        </link>
      </model>
      <model name='my_ground_plane'>
        <pose>5.49276 7.39463 0 0 -0 0</pose>
        <scale>1 1 1</scale>
        <link name='link'>
          <pose>5.49276 7.39463 0 0 -0 0</pose>
          <velocity>0 0 0 0 -0 0</velocity>
          <acceleration>0 0 0 0 -0 0</acceleration>
          <wrench>0 0 0 0 -0 0</wrench>
        </link>
      </model>
      <model name='mycar'>
        <pose>-0.003824 -0.00652 0.022856 -2e-06 0.000217 0.039626</pose>
        <scale>1 1 1</scale>
        <link name='base_link'>
          <pose>-0.003824 -0.00652 0.022856 -2e-06 0.000217 0.039626</pose>
          <velocity>0.000197 -2.8e-05 6e-06 1.4e-05 -0.000143 -0.000404</velocity>
          <acceleration>0.186474 -0.042926 0.010844 0.010813 -0.142975 -0.403648</acceleration>
          <wrench>3.1212 -0.718498 0.18151 0 -0 0</wrench>
        </link>
        <link name='wheel_lb_Link'>
          <pose>-0.143922 0.144798 0.050684 -1.3e-05 -0.51127 0.039633</pose>
          <velocity>0.000252 3.3e-05 -1.9e-05 -0.000672 0.00497 -0.000424</velocity>
          <acceleration>0.242291 0.032267 -0.008183 -0.558319 -1.31885 -0.424251</acceleration>
          <wrench>0.697143 0.092843 -0.023545 0 -0 0</wrench>
        </link>
        <link name='wheel_lf_Link'>
          <pose>0.123867 0.155415 0.050627 -1.8e-05 0.003226 0.039627</pose>
          <velocity>0.000234 -6.4e-05 8.3e-05 0.001261 0.004631 6e-05</velocity>
          <acceleration>0.235824 -0.063636 0.049763 -1.77547 -1.51211 -3.08166</acceleration>
          <wrench>0.678537 -0.183101 0.143182 0 -0 0</wrench>
        </link>
        <link name='wheel_rb_Link'>
          <pose>-0.131503 -0.168455 0.050685 0 -0.346143 0.039626</pose>
          <velocity>0.000126 3e-05 7e-06 -0.000618 0.00248 -0.000397</velocity>
          <acceleration>0.134768 0.029869 -0.004541 2.58092 0.668362 2.74418</acceleration>
          <wrench>0.387768 0.085942 -0.013067 0 -0 0</wrench>
        </link>
        <link name='wheel_rf_Link'>
          <pose>0.136287 -0.157838 0.050627 3.1e-05 0.165411 0.039634</pose>
          <velocity>0.000133 -7e-05 -2.4e-05 0.001282 0.002628 -0.000291</velocity>
          <acceleration>0.139747 -0.069419 0.00752 -1.80018 0.492548 2.85089</acceleration>
          <wrench>0.402093 -0.199739 0.021637 0 -0 0</wrench>
        </link>
      </model>
      <model name='thrift_shop'>
        <pose>5.95316 7.47278 0 0 -0 0</pose>
        <scale>1 1 1</scale>
        <link name='link'>
          <pose>5.95316 7.47278 0 0 -0 0</pose>
          <velocity>0 0 0 0 -0 0</velocity>
          <acceleration>0 0 0 0 -0 0</acceleration>
          <wrench>0 0 0 0 -0 0</wrench>
        </link>
      </model>
      <light name='sun'>
        <pose>0 0 10 0 -0 0</pose>
      </light>
    </state>
    <gui fullscreen='0'>
      <camera name='user_camera'>
        <pose>-21.748 23.944 40.1287 0 0.857796 -0.630995</pose>
        <view_controller>orbit</view_controller>
        <projection_type>perspective</projection_type>
      </camera>
    </gui>
    <model name='mycar'>
      <link name='base_link'>
        <inertial>
          <pose>0.032797 0.00331 0.087722 0 -0 0</pose>
          <mass>16.738</mass>
          <inertia>
            <ixx>0.0634912</ixx>
            <ixy>8.58846e-06</ixy>
            <ixz>2.0403e-05</ixz>
            <iyy>0.105707</iyy>
            <iyz>-4.04125e-06</iyz>
            <izz>0.158135</izz>
          </inertia>
        </inertial>
        <collision name='base_link_collision'>
          <pose>0 0 0 0 -0 0</pose>
          <geometry>
            <mesh>
              <scale>1 1 1</scale>
              <uri>/home/zyh973/catkin_car/src/car_model/meshes/base_link.STL</uri>
            </mesh>
          </geometry>
          <max_contacts>10</max_contacts>
          <surface>
            <contact>
              <ode/>
            </contact>
            <bounce/>
            <friction>
              <torsional>
                <ode/>
              </torsional>
              <ode/>
            </friction>
          </surface>
        </collision>
        <collision name='base_link_fixed_joint_lump__camera_collision_1'>
          <pose>0.1935 0 0.072 0 -0 0</pose>
          <geometry>
            <box>
              <size>0.033 0.175 0.03</size>
            </box>
          </geometry>
          <surface>
            <contact>
              <ode/>
            </contact>
            <friction>
              <ode/>
              <torsional>
                <ode/>
              </torsional>
            </friction>
            <bounce/>
          </surface>
          <max_contacts>10</max_contacts>
        </collision>
        <visual name='base_link_visual'>
          <pose>0 0 0 0 -0 0</pose>
          <geometry>
            <mesh>
              <scale>1 1 1</scale>
              <uri>/home/zyh973/catkin_car/src/car_model/meshes/base_link.STL</uri>
            </mesh>
          </geometry>
        </visual>
        <visual name='base_link_fixed_joint_lump__camera_visual_1'>
          <pose>0.1935 0 0.072 0 -0 0</pose>
          <geometry>
            <box>
              <size>0.033 0.175 0.03</size>
            </box>
          </geometry>
          <material>
            <script>
              <name>Gazebo/Blue</name>
              <uri>file://media/materials/scripts/gazebo.material</uri>
            </script>
          </material>
        </visual>
        <visual name='base_link_fixed_joint_lump__support_visual_2'>
          <pose>0 0 0 0 -0 0</pose>
          <geometry>
            <cylinder>
              <length>0</length>
              <radius>0</radius>
            </cylinder>
          </geometry>
        </visual>
        <visual name='base_link_fixed_joint_lump__laser_visual_3'>
          <pose>0.1345 0.035 0.1127 0 -0 0</pose>
          <geometry>
            <cylinder>
              <length>0.0452</length>
              <radius>0.0355</radius>
            </cylinder>
          </geometry>
        </visual>
        <sensor name='camera_node' type='camera'>
          <update_rate>30</update_rate>
          <camera name='head'>
            <horizontal_fov>1.39626</horizontal_fov>
            <image>
              <width>1280</width>
              <height>720</height>
              <format>R8G8B8</format>
            </image>
            <clip>
              <near>0.02</near>
              <far>300</far>
            </clip>
            <noise>
              <type>gaussian</type>
              <mean>0</mean>
              <stddev>0.007</stddev>
            </noise>
          </camera>
          <plugin name='gazebo_camera' filename='libgazebo_ros_camera.so'>
            <alwaysOn>1</alwaysOn>
            <updateRate>0.0</updateRate>
            <cameraName>/camera</cameraName>
            <imageTopicName>image_raw</imageTopicName>
            <cameraInfoTopicName>camera_info</cameraInfoTopicName>
            <frameName>camera</frameName>
            <hackBaseline>0.07</hackBaseline>
            <distortionK1>0.0</distortionK1>
            <distortionK2>0.0</distortionK2>
            <distortionK3>0.0</distortionK3>
            <distortionT1>0.0</distortionT1>
            <distortionT2>0.0</distortionT2>
            <robotNamespace>/</robotNamespace>
          </plugin>
          <pose>0.1935 0 0.072 0 -0 0</pose>
        </sensor>
        <sensor name='rplidar' type='ray'>
          <visualize>1</visualize>
          <update_rate>5.5</update_rate>
          <ray>
            <scan>
              <horizontal>
                <samples>64</samples>
                <resolution>1</resolution>
                <min_angle>-3</min_angle>
                <max_angle>3</max_angle>
              </horizontal>
              <vertical>
                <samples>1</samples>
                <min_angle>0</min_angle>
                <max_angle>0</max_angle>
              </vertical>
            </scan>
            <range>
              <min>0.1</min>
              <max>30</max>
              <resolution>0.01</resolution>
            </range>
            <noise>
              <type>gaussian</type>
              <mean>0</mean>
              <stddev>0.01</stddev>
            </noise>
          </ray>
          <plugin name='gazebo_rplidar' filename='libgazebo_ros_laser.so'>
            <topicName>/scan</topicName>
            <frameName>laser</frameName>
            <robotNamespace>/</robotNamespace>
          </plugin>
          <pose>0.1345 0.035 0.1127 0 -0 0</pose>
        </sensor>
        <self_collide>0</self_collide>
        <enable_wind>0</enable_wind>
        <kinematic>0</kinematic>
      </link>
      <joint name='wheel_lb_joint' type='revolute'>
        <pose relative_to='base_link'>-0.134 0.15675 0.0278 0 -0 0</pose>
        <parent>base_link</parent>
        <child>wheel_lb_Link</child>
        <axis>
          <xyz>0 -1 0</xyz>
          <limit>
            <lower>-1e+16</lower>
            <upper>1e+16</upper>
          </limit>
          <dynamics>
            <spring_reference>0</spring_reference>
            <spring_stiffness>0</spring_stiffness>
          </dynamics>
        </axis>
      </joint>
      <link name='wheel_lb_Link'>
        <pose relative_to='wheel_lb_joint'>0 0 0 0 -0 0</pose>
        <inertial>
          <pose>-0 -0.02275 0 0 -0 0</pose>
          <mass>2.8773</mass>
          <inertia>
            <ixx>0.0023527</ixx>
            <ixy>1.0128e-17</ixy>
            <ixz>-3.5376e-32</ixz>
            <iyy>0.0037126</iyy>
            <iyz>-4.7481e-18</iyz>
            <izz>0.0023527</izz>
          </inertia>
        </inertial>
        <collision name='wheel_lb_Link_collision'>
          <pose>0 0 0 0 -0 0</pose>
          <geometry>
            <mesh>
              <scale>1 1 1</scale>
              <uri>/home/zyh973/catkin_car/src/car_model/meshes/wheel_lb_Link.STL</uri>
            </mesh>
          </geometry>
          <max_contacts>10</max_contacts>
          <surface>
            <contact>
              <ode/>
            </contact>
            <bounce/>
            <friction>
              <torsional>
                <ode/>
              </torsional>
              <ode/>
            </friction>
          </surface>
        </collision>
        <visual name='wheel_lb_Link_visual'>
          <pose>0 0 0 0 -0 0</pose>
          <geometry>
            <mesh>
              <scale>1 1 1</scale>
              <uri>/home/zyh973/catkin_car/src/car_model/meshes/wheel_lb_Link.STL</uri>
            </mesh>
          </geometry>
        </visual>
        <self_collide>0</self_collide>
        <enable_wind>0</enable_wind>
        <kinematic>0</kinematic>
      </link>
      <joint name='wheel_lf_joint' type='revolute'>
        <pose relative_to='base_link'>0.134 0.15675 0.0278 0 -0 0</pose>
        <parent>base_link</parent>
        <child>wheel_lf_Link</child>
        <axis>
          <xyz>0 -1 0</xyz>
          <limit>
            <lower>-1e+16</lower>
            <upper>1e+16</upper>
          </limit>
          <dynamics>
            <spring_reference>0</spring_reference>
            <spring_stiffness>0</spring_stiffness>
          </dynamics>
        </axis>
      </joint>
      <link name='wheel_lf_Link'>
        <pose relative_to='wheel_lf_joint'>0 0 0 0 -0 0</pose>
        <inertial>
          <pose>-0 -0.02275 0 0 -0 0</pose>
          <mass>2.8773</mass>
          <inertia>
            <ixx>0.0023527</ixx>
            <ixy>1.0208e-17</ixy>
            <ixz>2.3485e-21</ixz>
            <iyy>0.0037126</iyy>
            <iyz>-4.7478e-18</iyz>
            <izz>0.0023527</izz>
          </inertia>
        </inertial>
        <collision name='wheel_lf_Link_collision'>
          <pose>0 0 0 0 -0 0</pose>
          <geometry>
            <mesh>
              <scale>1 1 1</scale>
              <uri>/home/zyh973/catkin_car/src/car_model/meshes/wheel_lf_Link.STL</uri>
            </mesh>
          </geometry>
          <max_contacts>10</max_contacts>
          <surface>
            <contact>
              <ode/>
            </contact>
            <bounce/>
            <friction>
              <torsional>
                <ode/>
              </torsional>
              <ode/>
            </friction>
          </surface>
        </collision>
        <visual name='wheel_lf_Link_visual'>
          <pose>0 0 0 0 -0 0</pose>
          <geometry>
            <mesh>
              <scale>1 1 1</scale>
              <uri>/home/zyh973/catkin_car/src/car_model/meshes/wheel_lf_Link.STL</uri>
            </mesh>
          </geometry>
        </visual>
        <self_collide>0</self_collide>
        <enable_wind>0</enable_wind>
        <kinematic>0</kinematic>
      </link>
      <joint name='wheel_rb_joint' type='revolute'>
        <pose relative_to='base_link'>-0.134 -0.15675 0.0278 0 -0 0</pose>
        <parent>base_link</parent>
        <child>wheel_rb_Link</child>
        <axis>
          <xyz>0 -1 0</xyz>
          <limit>
            <lower>-1e+16</lower>
            <upper>1e+16</upper>
          </limit>
          <dynamics>
            <spring_reference>0</spring_reference>
            <spring_stiffness>0</spring_stiffness>
          </dynamics>
        </axis>
      </joint>
      <link name='wheel_rb_Link'>
        <pose relative_to='wheel_rb_joint'>0 0 0 0 -0 0</pose>
        <inertial>
          <pose>0 0.02275 -0 0 -0 0</pose>
          <mass>2.8773</mass>
          <inertia>
            <ixx>0.0023527</ixx>
            <ixy>1.0128e-17</ixy>
            <ixz>-3.5357e-32</ixz>
            <iyy>0.0037126</iyy>
            <iyz>-4.7481e-18</iyz>
            <izz>0.0023527</izz>
          </inertia>
        </inertial>
        <collision name='wheel_rb_Link_collision'>
          <pose>0 0 0 0 -0 0</pose>
          <geometry>
            <mesh>
              <scale>1 1 1</scale>
              <uri>/home/zyh973/catkin_car/src/car_model/meshes/wheel_rb_Link.STL</uri>
            </mesh>
          </geometry>
          <max_contacts>10</max_contacts>
          <surface>
            <contact>
              <ode/>
            </contact>
            <bounce/>
            <friction>
              <torsional>
                <ode/>
              </torsional>
              <ode/>
            </friction>
          </surface>
        </collision>
        <visual name='wheel_rb_Link_visual'>
          <pose>0 0 0 0 -0 0</pose>
          <geometry>
            <mesh>
              <scale>1 1 1</scale>
              <uri>/home/zyh973/catkin_car/src/car_model/meshes/wheel_rb_Link.STL</uri>
            </mesh>
          </geometry>
        </visual>
        <self_collide>0</self_collide>
        <enable_wind>0</enable_wind>
        <kinematic>0</kinematic>
      </link>
      <joint name='wheel_rf_joint' type='revolute'>
        <pose relative_to='base_link'>0.134 -0.15675 0.0278 0 -0 0</pose>
        <parent>base_link</parent>
        <child>wheel_rf_Link</child>
        <axis>
          <xyz>0 -1 0</xyz>
          <limit>
            <lower>-1e+16</lower>
            <upper>1e+16</upper>
          </limit>
          <dynamics>
            <spring_reference>0</spring_reference>
            <spring_stiffness>0</spring_stiffness>
          </dynamics>
        </axis>
      </joint>
      <link name='wheel_rf_Link'>
        <pose relative_to='wheel_rf_joint'>0 0 0 0 -0 0</pose>
        <inertial>
          <pose>0 0.02275 -0 0 -0 0</pose>
          <mass>2.8773</mass>
          <inertia>
            <ixx>0.0023527</ixx>
            <ixy>1.0128e-17</ixy>
            <ixz>-3.5357e-32</ixz>
            <iyy>0.0037126</iyy>
            <iyz>-4.7481e-18</iyz>
            <izz>0.0023527</izz>
          </inertia>
        </inertial>
        <collision name='wheel_rf_Link_collision'>
          <pose>0 0 0 0 -0 0</pose>
          <geometry>
            <mesh>
              <scale>1 1 1</scale>
              <uri>/home/zyh973/catkin_car/src/car_model/meshes/wheel_rf_Link.STL</uri>
            </mesh>
          </geometry>
          <max_contacts>10</max_contacts>
          <surface>
            <contact>
              <ode/>
            </contact>
            <bounce/>
            <friction>
              <torsional>
                <ode/>
              </torsional>
              <ode/>
            </friction>
          </surface>
        </collision>
        <visual name='wheel_rf_Link_visual'>
          <pose>0 0 0 0 -0 0</pose>
          <geometry>
            <mesh>
              <scale>1 1 1</scale>
              <uri>/home/zyh973/catkin_car/src/car_model/meshes/wheel_rf_Link.STL</uri>
            </mesh>
          </geometry>
        </visual>
        <self_collide>0</self_collide>
        <enable_wind>0</enable_wind>
        <kinematic>0</kinematic>
      </link>
      <plugin name='skid_steer_drive_controller' filename='libgazebo_ros_planar_move.so'>
        <rosDebugLevel>Debug</rosDebugLevel>
        <publishWheelTF>1</publishWheelTF>
        <robotNamespace>/</robotNamespace>
        <publishTf>1</publishTf>
        <publishWheelJointState>1</publishWheelJointState>
        <alwaysOn>1</alwaysOn>
        <updateRate>100.0</updateRate>
        <legacyMode>1</legacyMode>
        <leftFrontJoint>wheel_lf_joint</leftFrontJoint>
        <rightFrontJoint>wheel_rf_joint</rightFrontJoint>
        <leftRearJoint>wheel_lb_joint</leftRearJoint>
        <rightRearJoint>wheel_rb_joint</rightRearJoint>
        <wheelSeparation>4.65</wheelSeparation>
        <wheelDiameter>1.5</wheelDiameter>
        <broadcastTF>1</broadcastTF>
        <wheelTorque>100</wheelTorque>
        <wheelAcceleration>1.8</wheelAcceleration>
        <commandTopic>cmd_vel</commandTopic>
        <odometryFrame>odom</odometryFrame>
        <odometryTopic>odom</odometryTopic>
        <robotBaseFrame>base_link</robotBaseFrame>
      </plugin>
      <static>0</static>
      <plugin name='p3d_base_controller' filename='libgazebo_ros_p3d.so'>
        <alwaysOn>1</alwaysOn>
        <updateRate>100.0</updateRate>
        <bodyName>base_link</bodyName>
        <topicName>base_pose_ground_truth</topicName>
        <gaussianNoise>0.01</gaussianNoise>
        <frameName>world</frameName>
        <xyzOffsets>0 0 0</xyzOffsets>
        <rpyOffsets>0 0 0</rpyOffsets>
        <robotNamespace>/</robotNamespace>
      </plugin>
      <pose>0 0 0 0 -0 0</pose>
    </model>
  </world>
</sdf>
